2021-09-16 14:29:30,661 [INFO ]  Starting Rasa server on http://localhost:5005
2021-09-16 14:29:30,677 [INFO ]  Loading model models/20210916-142414.tar.gz...
2021-09-16 14:29:32,423 [INFO ]  Loading model models/20210916-142414.tar.gz...
2021-09-16 14:29:51,145 [WARNI]  The UnexpecTED Intent Policy is currently experimental and might change or be removed in the future ðŸ”¬ Please share your feedback on it in the forum (https://forum.rasa.com) to help us make this feature ready for production.
2021-09-16 14:29:58,680 [INFO ]  Rasa server is up and running.
2021-09-16 14:37:53,877 [ERROR]  Exception occurred while handling uri: 'http://localhost:5005/webhooks/rest/webhook'
Traceback (most recent call last):
  File "/home/naver/workspace/sdmbot/development/virtualenv/lib/python3.7/site-packages/sanic/app.py", line 931, in handle_request
    response = await response
  File "/home/naver/workspace/sdmbot/development/virtualenv/lib/python3.7/site-packages/rasa/core/channels/rest.py", line 101, in receive
    sender_id = await self._extract_sender(request)
  File "/home/naver/workspace/sdmbot/development/virtualenv/lib/python3.7/site-packages/rasa/core/channels/rest.py", line 52, in _extract_sender
    return req.json.get("sender", None)
AttributeError: 'NoneType' object has no attribute 'get'
2021-09-16 16:34:46,731 [ERROR]  Exception occurred while handling uri: 'http://localhost:5005/webhooks/rest/webhook'
Traceback (most recent call last):
  File "/home/naver/workspace/sdmbot/development/virtualenv/lib/python3.7/site-packages/sanic/app.py", line 931, in handle_request
    response = await response
  File "/home/naver/workspace/sdmbot/development/virtualenv/lib/python3.7/site-packages/rasa/core/channels/rest.py", line 101, in receive
    sender_id = await self._extract_sender(request)
  File "/home/naver/workspace/sdmbot/development/virtualenv/lib/python3.7/site-packages/rasa/core/channels/rest.py", line 52, in _extract_sender
    return req.json.get("sender", None)
AttributeError: 'NoneType' object has no attribute 'get'
2021-09-16 16:35:47,547 [ERROR]  Exception occurred while handling uri: 'http://localhost:5005/webhooks/rest/webhook'
Traceback (most recent call last):
  File "/home/naver/workspace/sdmbot/development/virtualenv/lib/python3.7/site-packages/sanic/app.py", line 931, in handle_request
    response = await response
  File "/home/naver/workspace/sdmbot/development/virtualenv/lib/python3.7/site-packages/rasa/core/channels/rest.py", line 101, in receive
    sender_id = await self._extract_sender(request)
  File "/home/naver/workspace/sdmbot/development/virtualenv/lib/python3.7/site-packages/rasa/core/channels/rest.py", line 52, in _extract_sender
    return req.json.get("sender", None)
AttributeError: 'NoneType' object has no attribute 'get'
